Traceback (most recent call last):
  File "C:\Users\NikiR\AppData\Local\Programs\Python\Python312\Lib\site-packages\jupyter_cache\executors\utils.py", line 58, in single_nb_execution
    executenb(
  File "C:\Users\NikiR\AppData\Local\Programs\Python\Python312\Lib\site-packages\nbclient\client.py", line 1314, in execute
    return NotebookClient(nb=nb, resources=resources, km=km, **kwargs).execute()
           ^^^^^^^^^^^^^^^^^^^^^^^^^^^^^^^^^^^^^^^^^^^^^^^^^^^^^^^^^^^^^^^^^^^^^
  File "C:\Users\NikiR\AppData\Local\Programs\Python\Python312\Lib\site-packages\jupyter_core\utils\__init__.py", line 165, in wrapped
    return loop.run_until_complete(inner)
           ^^^^^^^^^^^^^^^^^^^^^^^^^^^^^^
  File "C:\Users\NikiR\AppData\Local\Programs\Python\Python312\Lib\asyncio\base_events.py", line 687, in run_until_complete
    return future.result()
           ^^^^^^^^^^^^^^^
  File "C:\Users\NikiR\AppData\Local\Programs\Python\Python312\Lib\site-packages\nbclient\client.py", line 709, in async_execute
    await self.async_execute_cell(
  File "C:\Users\NikiR\AppData\Local\Programs\Python\Python312\Lib\site-packages\nbclient\client.py", line 1062, in async_execute_cell
    await self._check_raise_for_error(cell, cell_index, exec_reply)
  File "C:\Users\NikiR\AppData\Local\Programs\Python\Python312\Lib\site-packages\nbclient\client.py", line 918, in _check_raise_for_error
    raise CellExecutionError.from_cell_and_msg(cell, exec_reply_content)
nbclient.exceptions.CellExecutionError: An error occurred while executing the following cell:
------------------
import pandas as pd
import matplotlib.pyplot as plt
import seaborn as sns 

plt.figure(figsize=(12, 6))
sns.lineplot(data=df_main, x='Date', y='PM10', label='PM10')
sns.lineplot(data=df_main, x='Date', y='PM2.5', label='PM2.5')
sns.lineplot(data=df_main, x='Date', y='SO2', label='SO2')
sns.lineplot(data=df_main, x='Date', y='CO', label='CO')
sns.lineplot(data=df_main, x='Date', y='O3', label='O3')
sns.lineplot(data=df_main, x='Date', y='NO2', label='NO2')
plt.xlabel('Date')
plt.ylabel('Pollutant Concentration')
plt.title('Air Quality in Yogyakarta (2021)')
plt.legend()
plt.show()
------------------


[1;31m---------------------------------------------------------------------------[0m
[1;31mModuleNotFoundError[0m                       Traceback (most recent call last)
Cell [1;32mIn[4], line 3[0m
[0;32m      1[0m [38;5;28;01mimport[39;00m [38;5;21;01mpandas[39;00m [38;5;28;01mas[39;00m [38;5;21;01mpd[39;00m
[0;32m      2[0m [38;5;28;01mimport[39;00m [38;5;21;01mmatplotlib[39;00m[38;5;21;01m.[39;00m[38;5;21;01mpyplot[39;00m [38;5;28;01mas[39;00m [38;5;21;01mplt[39;00m
[1;32m----> 3[0m [38;5;28;01mimport[39;00m [38;5;21;01mseaborn[39;00m [38;5;28;01mas[39;00m [38;5;21;01msns[39;00m 
[0;32m      5[0m plt[38;5;241m.[39mfigure(figsize[38;5;241m=[39m([38;5;241m12[39m, [38;5;241m6[39m))
[0;32m      6[0m sns[38;5;241m.[39mlineplot(data[38;5;241m=[39mdf_main, x[38;5;241m=[39m[38;5;124m'[39m[38;5;124mDate[39m[38;5;124m'[39m, y[38;5;241m=[39m[38;5;124m'[39m[38;5;124mPM10[39m[38;5;124m'[39m, label[38;5;241m=[39m[38;5;124m'[39m[38;5;124mPM10[39m[38;5;124m'[39m)

[1;31mModuleNotFoundError[0m: No module named 'seaborn'

